Workbook

Sheet Sample Setup
A1: Experiment Details:
A2: Block Type: | B2: 0.1 mL
A3: Chemistry: | B3: TAQMAN
A4: Date Created: | B4: 17 Jul 2026 11:00:56 GMT-0700
A5: Barcode:
A6: Comments: | B6: Update protein concentration Correct dilutions Correct spike information For HCCP and ProA
A7: Experiment Name: | B7: 2026-07-17_MD_R3_GR
A8: Experiment Run End Time: | B8: 17 Jul 2026 16:14:21 GMT-0700
A9: Experiment Type: | B9: Standard Curve
A10: Instrument Name: | B10: 272513207
A11: Instrument Serial Number: | B11: 272513207
A12: Instrument Type: | B12: QuantStudio™ 5
A13: Passive Reference: | B13: ROX
A14: E-Sig Status: | B14: Unsigned
A15: E-Sig By: | B15: NA
A16: Fit: | B16: Linear
A17: Weighting: | B17: None
A18: Formula: | B18: N/A
A19: Target: | B19: CHO | C19: R2 : 0.9998 | D19: Slope : -3.3008 | E19: y-Intercept : 21.3153 | F19: Efficiency : 100.89 | G19: Std error : 0.0116
A23: Well | B23: Well Position | C23: Sample Name | D23: Sample Color | E23: Target Name | F23: Target Color | G23: Task | H23: Reporter | I23: Quencher | J23: Quantity | K23: Comments
A24: A1 | B24: 1 | C24: NTC | D24: RGB(77,77,77) | E24: CHO | F24: RGB(255,0,0) | G24: NTC | H24: FAM | I24: NONE
A25: A2 | B25: 2 | C25: NTC | D25: RGB(77,77,77) | E25: CHO | F25: RGB(255,0,0) | G25: NTC | H25: FAM | I25: NONE
A26: A3 | B26: 3 | C26: NTC | D26: RGB(77,77,77) | E26: CHO | F26: RGB(255,0,0) | G26: NTC | H26: FAM | I26: NONE
A27: A4 | B27: 4 | C27: S1 D1 | D27: RGB(23,190,207) | E27: CHO | F27: RGB(255,0,0) | G27: UNKNOWN | H27: FAM | I27: NONE
A28: A5 | B28: 5 | C28: S1 D1 | D28: RGB(23,190,207) | E28: CHO | F28: RGB(255,0,0) | G28: UNKNOWN | H28: FAM | I28: NONE
A29: A6 | B29: 6 | C29: S1 D1 | D29: RGB(23,190,207) | E29: CHO | F29: RGB(255,0,0) | G29: UNKNOWN | H29: FAM | I29: NONE
A30: A7 | B30: 7 | C30: ERC - 60 | D30: RGB(140,86,75) | E30: CHO | F30: RGB(255,0,0) | G30: UNKNOWN | H30: FAM | I30: NONE
A31: A8 | B31: 8 | C31: ERC - 60 | D31: RGB(140,86,75) | E31: CHO | F31: RGB(255,0,0) | G31: UNKNOWN | H31: FAM | I31: NONE
A32: A9 | B32: 9 | C32: ERC - 60 | D32: RGB(140,86,75) | E32: CHO | F32: RGB(255,0,0) | G32: UNKNOWN | H32: FAM | I32: NONE
A33: A10 | B33: 10 | C33: STD 300 | D33: RGB(227,119,194) | E33: CHO | F33: RGB(255,0,0) | G33: STANDARD | H33: FAM | I33: NONE | J33: 300
A34: A11 | B34: 11 | C34: STD 300 | D34: RGB(227,119,194) | E34: CHO | F34: RGB(255,0,0) | G34: STANDARD | H34: FAM | I34: NONE | J34: 300
A35: A12 | B35: 12 | C35: STD 300 | D35: RGB(227,119,194) | E35: CHO | F35: RGB(255,0,0) | G35: STANDARD | H35: FAM | I35: NONE | J35: 300
A36: B1 | B36: 13 | C36: NEC - FB | D36: RGB(77,77,77) | E36: CHO | F36: RGB(255,0,0) | G36: NTC | H36: FAM | I36: NONE
A37: B2 | B37: 14 | C37: NEC - FB | D37: RGB(77,77,77) | E37: CHO | F37: RGB(255,0,0) | G37: NTC | H37: FAM | I37: NONE
A38: B3 | B38: 15 | C38: NEC - FB | D38: RGB(77,77,77) | E38: CHO | F38: RGB(255,0,0) | G38: NTC | H38: FAM | I38: NONE
A39: B4 | B39: 16 | C39: S1 D2 | D39: RGB(31,119,180) | E39: CHO | F39: RGB(255,0,0) | G39: UNKNOWN | H39: FAM | I39: NONE
A40: B5 | B40: 17 | C40: S1 D2 | D40: RGB(31,119,180) | E40: CHO | F40: RGB(255,0,0) | G40: UNKNOWN | H40: FAM | I40: NONE
A41: B6 | B41: 18 | C41: S1 D2 | D41: RGB(31,119,180) | E41: CHO | F41: RGB(255,0,0) | G41: UNKNOWN | H41: FAM | I41: NONE
A42: B7 | B42: 19 | C42: ERC - 30 | D42: RGB(255,127,14) | E42: CHO | F42: RGB(255,0,0) | G42: UNKNOWN | H42: FAM | I42: NONE
A43: B8 | B43: 20 | C43: ERC - 30 | D43: RGB(255,127,14) | E43: CHO | F43: RGB(255,0,0) | G43: UNKNOWN | H43: FAM | I43: NONE
...

Sheet Results
A1: Experiment Details:
A2: Block Type: | B2: 0.1 mL
A3: Chemistry: | B3: TAQMAN
A4: Date Created: | B4: 17 Jul 2026 11:00:56 GMT-0700
A5: Barcode:
A6: Comments: | B6: Update protein concentration Correct dilutions Correct spike information For HCCP and ProA
A7: Experiment Name: | B7: 2026-07-17_MD_R3_GR
A8: Experiment Run End Time: | B8: 17 Jul 2026 16:14:21 GMT-0700
A9: Experiment Type: | B9: Standard Curve
A10: Instrument Name: | B10: 272513207
A11: Instrument Serial Number: | B11: 272513207
A12: Instrument Type: | B12: QuantStudio™ 5
A13: Passive Reference: | B13: ROX
A14: E-Sig Status: | B14: Unsigned
A15: E-Sig By: | B15: NA
A16: Fit: | B16: Linear
A17: Weighting: | B17: None
A18: Formula: | B18: N/A
A19: Target: | B19: CHO | C19: R2 : 0.9998 | D19: Slope : -3.3008 | E19: y-Intercept : 21.3153 | F19: Efficiency : 100.89 | G19: Std error : 0.0116
A23: Well | B23: Well Position | C23: Task | D23: Sample Name | E23: Target Name | F23: Ct | G23: Ct Mean | H23: Ct CV% | I23: Ct SD | J23: Quantity | K23: Quantity Mean | L23: Quantity SD | M23: Quantity %CV | N23: Dilution Factor | O23: Dilution Adjusted | P23: % Recovery | Q23: R2 | R23: Slope | S23: Y-Intercept | T23: Total DNA per mL | U23: Total DNA per Protein Concentration | V23: Flag | W23: Ct Threshold | X23: Automatic Ct Threshold | Y23: CQ Confidence | Z23: Automatic Baseline | AA23: Baseline Start | AB23: Baseline End | AC23: Reference | AD23: Reference Adjusted | AE23: Spike Input | AF23: Back calculated value | AG23: Back Calculation Mean | AH23: Back Calculation %CV | AI23: Back Calculation SD | AJ23: Back Calculation % difference | AK23: Back Calculation % difference Mean | AL23: Fit | AM23: Amplification Efficiency | AN23: Amplification Status | AO23: AMPNC | AP23: NOAMP | AQ23: EXPFAIL | AR23: Protein Concentration | AS23: CQCONF
A24: A1 | B24: 1 | C24: NTC | D24: NTC | E24: CHO | F24: Undetermined | N24: 1 | Q24: 0.9998 | R24: -3.3008 | S24: 21.3153 | T24: 0 | V24: 0 | W24: 0.207 | X24: true | Y24: 0 | Z24: Yes | AA24: 3 | AB24: 39 | AE24: 0 | AL24: Linear | AM24: 100.89 | AN24: No Amp | AO24: N | AP24: N | AQ24: N | AS24: N
A25: A2 | B25: 2 | C25: NTC | D25: NTC | E25: CHO | F25: Undetermined | N25: 1 | Q25: 0.9998 | R25: -3.3008 | S25: 21.3153 | T25: 0 | V25: 0 | W25: 0.207 | X25: true | Y25: 0 | Z25: Yes | AA25: 3 | AB25: 39 | AE25: 0 | AL25: Linear | AM25: 100.89 | AN25: No Amp | AO25: N | AP25: N | AQ25: N | AS25: N
A26: A3 | B26: 3 | C26: NTC | D26: NTC | E26: CHO | F26: Undetermined | N26: 1 | Q26: 0.9998 | R26: -3.3008 | S26: 21.3153 | T26: 0 | V26: 0 | W26: 0.207 | X26: true | Y26: 0 | Z26: Yes | AA26: 3 | AB26: 39 | AE26: 0 | AL26: Linear | AM26: 100.89 | AN26: No Amp | AO26: N | AP26: N | AQ26: N | AS26: N
A27: A4 | B27: 4 | C27: UNKNOWN | D27: S1 D1 | E27: CHO | F27: 32.3647 | G27: 32.5183 | H27: 0.81 | I27: 0.2622 | J27: 0.0004 | K27: 0.0004 | L27: 0.0001 | M27: 17.24 | N27: 1 | O27: 0.0004 | Q27: 0.9998 | R27: -3.3008 | S27: 21.3153 | T27: 0.0004 | U27: 0.0002 | V27: 0 | W27: 0.207 | X27: true | Y27: 1 | Z27: Yes | AA27: 3 | AB27: 27 | AC27: 0 | AD27: 0.0004 | AE27: 0 | AL27: Linear | AM27: 100.89 | AN27: Amplification | AO27: N | AP27: N | AQ27: N | AR27: 1.825 | AS27: N
A28: A5 | B28: 5 | C28: UNKNOWN | D28: S1 D1 | E28: CHO | F28: 32.3692 | G28: 32.5183 | H28: 0.81 | I28: 0.2622 | J28: 0.0004 | K28: 0.0004 | L28: 0.0001 | M28: 17.24 | N28: 1 | O28: 0.0004 | Q28: 0.9998 | R28: -3.3008 | S28: 21.3153 | T28: 0.0004 | U28: 0.0002 | V28: 0 | W28: 0.207 | X28: true | Y28: 1 | Z28: Yes | AA28: 3 | AB28: 28 | AC28: 0 | AD28: 0.0004 | AE28: 0 | AL28: Linear | AM28: 100.89 | AN28: Amplification | AO28: N | AP28: N | AQ28: N | AR28: 1.825 | AS28: N
A29: A6 | B29: 6 | C29: UNKNOWN | D29: S1 D1 | E29: CHO | F29: 32.8211 | G29: 32.5183 | H29: 0.81 | I29: 0.2622 | J29: 0.0003 | K29: 0.0004 | L29: 0.0001 | M29: 17.24 | N29: 1 | O29: 0.0004 | Q29: 0.9998 | R29: -3.3008 | S29: 21.3153 | T29: 0.0004 | U29: 0.0002 | V29: 0 | W29: 0.207 | X29: true | Y29: 1 | Z29: Yes | AA29: 3 | AB29: 26 | AC29: 0 | AD29: 0.0004 | AE29: 0 | AL29: Linear | AM29: 100.89 | AN29: Amplification | AO29: N | AP29: N | AQ29: N | AR29: 1.825 | AS29: N
A30: A7 | B30: 7 | C30: UNKNOWN | D30: ERC - 60 | E30: CHO | F30: 15.9329 | G30: 15.9407 | H30: 0.28 | I30: 0.044 | J30: 42.7195 | K30: 42.5016 | L30: 1.2996 | M30: 3.06 | N30: 1 | O30: 42.5016 | P30: 70.84 | Q30: 0.9998 | R30: -3.3008 | S30: 21.3153 | T30: 42.5016 | V30: 0 | W30: 0.207 | X30: true | Y30: 1 | Z30: Yes | AA30: 3 | AB30: 10 | AC30: 0 | AD30: 42.5016 | AE30: 60 | AL30: Linear | AM30: 100.89 | AN30: Amplification | AO30: N | AP30: N | AQ30: N | AS30: N
A31: A8 | B31: 8 | C31: UNKNOWN | D31: ERC - 60 | E31: CHO | F31: 15.9881 | G31: 15.9407 | H31: 0.28 | I31: 0.044 | J31: 41.1069 | K31: 42.5016 | L31: 1.2996 | M31: 3.06 | N31: 1 | O31: 42.5016 | P31: 70.84 | Q31: 0.9998 | R31: -3.3008 | S31: 21.3153 | T31: 42.5016 | V31: 0 | W31: 0.207 | X31: true | Y31: 1 | Z31: Yes | AA31: 3 | AB31: 11 | AC31: 0 | AD31: 42.5016 | AE31: 60 | AL31: Linear | AM31: 100.89 | AN31: Amplification | AO31: N | AP31: N | AQ31: N | AS31: N
A32: A9 | B32: 9 | C32: UNKNOWN | D32: ERC - 60 | E32: CHO | F32: 15.9011 | G32: 15.9407 | H32: 0.28 | I32: 0.044 | J32: 43.6785 | K32: 42.5016 | L32: 1.2996 | M32: 3.06 | N32: 1 | O32: 42.5016 | P32: 70.84 | Q32: 0.9998 | R32: -3.3008 | S32: 21.3153 | T32: 42.5016 | V32: 0 | W32: 0.207 | X32: true | Y32: 1 | Z32: Yes | AA32: 3 | AB32: 9 | AC32: 0 | AD32: 42.5016 | AE32: 60 | AL32: Linear | AM32: 100.89 | AN32: Amplification | AO32: N | AP32: N | AQ32: N | AS32: N
A33: A10 | B33: 10 | C33: STANDARD | D33: STD 300 | E33: CHO | F33: 13.2588 | G33: 13.1972 | H33: 0.46 | I33: 0.0605 | J33: 300 | N33: 1 | Q33: 0.9998 | R33: -3.3008 | S33: 21.3153 | T33: 0 | V33: 0 | W33: 0.207 | X33: true | Y33: 1 | Z33: Yes | AA33: 3 | AB33: 9 | AE33: 0 | AF33: 275.9091 | AG33: 288.2029 | AH33: 4.21 | AI33: 12.1357 | AJ33: 8.03 | AK33: 3.9324 | AL33: Linear | AM33: 100.89 | AN33: Amplification | AO33: N | AP33: N | AQ33: N | AS33: N
A34: A11 | B34: 11 | C34: STANDARD | D34: STD 300 | E34: CHO | F34: 13.1947 | G34: 13.1972 | H34: 0.46 | I34: 0.0605 | J34: 300 | N34: 1 | Q34: 0.9998 | R34: -3.3008 | S34: 21.3153 | T34: 0 | V34: 0 | W34: 0.207 | X34: true | Y34: 1 | Z34: Yes | AA34: 3 | AB34: 9 | AE34: 0 | AF34: 288.5257 | AG34: 288.2029 | AH34: 4.21 | AI34: 12.1357 | AJ34: 3.82 | AK34: 3.9324 | AL34: Linear | AM34: 100.89 | AN34: Amplification | AO34: N | AP34: N | AQ34: N | AS34: N
A35: A12 | B35: 12 | C35: STANDARD | D35: STD 300 | E35: CHO | F35: 13.138 | G35: 13.1972 | H35: 0.46 | I35: 0.0605 | J35: 300 | N35: 1 | Q35: 0.9998 | R35: -3.3008 | S35: 21.3153 | T35: 0 | V35: 0 | W35: 0.207 | X35: true | Y35: 1 | Z35: Yes | AA35: 3 | AB35: 8 | AE35: 0 | AF35: 300.174 | AG35: 288.2029 | AH35: 4.21 | AI35: 12.1357 | AJ35: -0.06 | AK35: 3.9324 | AL35: Linear | AM35: 100.89 | AN35: Amplification | AO35: N | AP35: N | AQ35: N | AS35: N
A36: B1 | B36: 13 | C36: NTC | D36: NEC - FB | E36: CHO | F36: 28.6104 | N36: 1 | Q36: 0.9998 | R36: -3.3008 | S36: 21.3153 | T36: 0 | V36: 1 | W36: 0.207 | X36: true | Y36: 1 | Z36: Yes | AA36: 3 | AB36: 23 | AE36: 0 | AL36: Linear | AM36: 100.89 | AN36: Amplification | AO36: Y | AP36: N | AQ36: N | AS36: N
A37: B2 | B37: 14 | C37: NTC | D37: NEC - FB | E37: CHO | F37: 28.5299 | N37: 1 | Q37: 0.9998 | R37: -3.3008 | S37: 21.3153 | T37: 0 | V37: 1 | W37: 0.207 | X37: true | Y37: 1 | Z37: Yes | AA37: 3 | AB37: 22 | AE37: 0 | AL37: Linear | AM37: 100.89 | AN37: Amplification | AO37: Y | AP37: N | AQ37: N | AS37: N
A38: B3 | B38: 15 | C38: NTC | D38: NEC - FB | E38: CHO | F38: 28.4455 | N38: 1 | Q38: 0.9998 | R38: -3.3008 | S38: 21.3153 | T38: 0 | V38: 1 | W38: 0.207 | X38: true | Y38: 1 | Z38: Yes | AA38: 3 | AB38: 22 | AE38: 0 | AL38: Linear | AM38: 100.89 | AN38: Amplification | AO38: Y | AP38: N | AQ38: N | AS38: N
A39: B4 | B39: 16 | C39: UNKNOWN | D39: S1 D2 | E39: CHO | F39: 35.7364 | G39: 35.8319 | H39: 0.91 | I39: 0.3254 | J39: 0 | K39: 0 | L39: 0 | M39: 21.52 | N39: 10 | O39: 0.0004 | Q39: 0.9998 | R39: -3.3008 | S39: 21.3153 | T39: 0.0004 | U39: 0.0002 | V39: 0 | W39: 0.207 | X39: true | Y39: 1 | Z39: Yes | AA39: 3 | AB39: 30 | AC39: 0 | AD39: 0 | AE39: 0 | AL39: Linear | AM39: 100.89 | AN39: Amplification | AO39: N | AP39: N | AQ39: N | AR39: 1.825 | AS39: N
A40: B5 | B40: 17 | C40: UNKNOWN | D40: S1 D2 | E40: CHO | F40: 35.5648 | G40: 35.8319 | H40: 0.91 | I40: 0.3254 | J40: 0 | K40: 0 | L40: 0 | M40: 21.52 | N40: 10 | O40: 0.0004 | Q40: 0.9998 | R40: -3.3008 | S40: 21.3153 | T40: 0.0004 | U40: 0.0002 | V40: 0 | W40: 0.207 | X40: true | Y40: 1 | Z40: Yes | AA40: 3 | AB40: 30 | AC40: 0 | AD40: 0 | AE40: 0 | AL40: Linear | AM40: 100.89 | AN40: Amplification | AO40: N | AP40: N | AQ40: N | AR40: 1.825 | AS40: N
A41: B6 | B41: 18 | C41: UNKNOWN | D41: S1 D2 | E41: CHO | F41: 36.1944 | G41: 35.8319 | H41: 0.91 | I41: 0.3254 | J41: 0 | K41: 0 | L41: 0 | M41: 21.52 | N41: 10 | O41: 0.0004 | Q41: 0.9998 | R41: -3.3008 | S41: 21.3153 | T41: 0.0004 | U41: 0.0002 | V41: 0 | W41: 0.207 | X41: true | Y41: 1 | Z41: Yes | AA41: 3 | AB41: 30 | AC41: 0 | AD41: 0 | AE41: 0 | AL41: Linear | AM41: 100.89 | AN41: Amplification | AO41: N | AP41: N | AQ41: N | AR41: 1.825 | AS41: N
A42: B7 | B42: 19 | C42: UNKNOWN | D42: ERC - 30 | E42: CHO | F42: 17.0421 | G42: 17.0158 | H42: 0.16 | I42: 0.0274 | J42: 19.7065 | K42: 20.0732 | L42: 0.3835 | M42: 1.91 | N42: 1 | O42: 20.0732 | P42: 66.91 | Q42: 0.9998 | R42: -3.3008 | S42: 21.3153 | T42: 20.0732 | V42: 0 | W42: 0.207 | X42: true | Y42: 1 | Z42: Yes | AA42: 3 | AB42: 12 | AC42: 0 | AD42: 20.0732 | AE42: 30 | AL42: Linear | AM42: 100.89 | AN42: Amplification | AO42: N | AP42: N | AQ42: N | AS42: N
A43: B8 | B43: 20 | C43: UNKNOWN | D43: ERC - 30 | E43: CHO | F43: 17.0179 | G43: 17.0158 | H43: 0.16 | I43: 0.0274 | J43: 20.0415 | K43: 20.0732 | L43: 0.3835 | M43: 1.91 | N43: 1 | O43: 20.0732 | P43: 66.91 | Q43: 0.9998 | R43: -3.3008 | S43: 21.3153 | T43: 20.0732 | V43: 0 | W43: 0.207 | X43: true | Y43: 1 | Z43: Yes | AA43: 3 | AB43: 12 | AC43: 0 | AD43: 20.0732 | AE43: 30 | AL43: Linear | AM43: 100.89 | AN43: Amplification | AO43: N | AP43: N | AQ43: N | AS43: N
...

Sheet Amplification Data
A1: Experiment Details:
A2: Block Type: | B2: 0.1 mL
A3: Chemistry: | B3: TAQMAN
A4: Date Created: | B4: 17 Jul 2026 11:00:56 GMT-0700
A5: Barcode:
A6: Comments: | B6: Update protein concentration Correct dilutions Correct spike information For HCCP and ProA
A7: Experiment Name: | B7: 2026-07-17_MD_R3_GR
A8: Experiment Run End Time: | B8: 17 Jul 2026 16:14:21 GMT-0700
A9: Experiment Type: | B9: Standard Curve
A10: Instrument Name: | B10: 272513207
A11: Instrument Serial Number: | B11: 272513207
A12: Instrument Type: | B12: QuantStudio™ 5
A13: Passive Reference: | B13: ROX
A14: E-Sig Status: | B14: Unsigned
A15: E-Sig By: | B15: NA
A16: Fit: | B16: Linear
A17: Weighting: | B17: None
A18: Formula: | B18: N/A
A19: Target: | B19: CHO | D19: R2 : 0.9998 | E19: Slope : -3.3008 | F19: y-Intercept : 21.3153 | G19: Efficiency : 100.89 | H19: Std error : 0.0116
A23: Well | B23: Well Position | C23: Sample Name | D23: Cycle | E23: Target Name | F23: Rn | G23: ΔRn
A24: A1 | B24: 1 | C24: =_xlfn.XLOOKUP(B24,Results!$B$23:$B$119,Results!$D$23:$D$119) | D24: 1 | E24: CHO | F24: 2.1254 | G24: 0.003195
A25: A1 | B25: 1 | C25: =_xlfn.XLOOKUP(B25,Results!$B$23:$B$119,Results!$D$23:$D$119) | D25: 2 | E25: CHO | F25: 2.132 | G25: 0.006404
A26: A1 | B26: 1 | C26: =_xlfn.XLOOKUP(B26,Results!$B$23:$B$119,Results!$D$23:$D$119) | D26: 3 | E26: CHO | F26: 2.1351 | G26: 0.006184
A27: A1 | B27: 1 | C27: =_xlfn.XLOOKUP(B27,Results!$B$23:$B$119,Results!$D$23:$D$119) | D27: 4 | E27: CHO | F27: 2.136 | G27: 0.003646
A28: A1 | B28: 1 | C28: =_xlfn.XLOOKUP(B28,Results!$B$23:$B$119,Results!$D$23:$D$119) | D28: 5 | E28: CHO | F28: 2.1381 | G28: 0.002378
A29: A1 | B29: 1 | C29: =_xlfn.XLOOKUP(B29,Results!$B$23:$B$119,Results!$D$23:$D$119) | D29: 6 | E29: CHO | F29: 2.1389 | G29: -0.000174
A30: A1 | B30: 1 | C30: =_xlfn.XLOOKUP(B30,Results!$B$23:$B$119,Results!$D$23:$D$119) | D30: 7 | E30: CHO | F30: 2.1453 | G30: 0.002803
A31: A1 | B31: 1 | C31: =_xlfn.XLOOKUP(B31,Results!$B$23:$B$119,Results!$D$23:$D$119) | D31: 8 | E31: CHO | F31: 2.1474 | G31: 0.001485
A32: A1 | B32: 1 | C32: =_xlfn.XLOOKUP(B32,Results!$B$23:$B$119,Results!$D$23:$D$119) | D32: 9 | E32: CHO | F32: 2.1468 | G32: -0.002467
A33: A1 | B33: 1 | C33: =_xlfn.XLOOKUP(B33,Results!$B$23:$B$119,Results!$D$23:$D$119) | D33: 10 | E33: CHO | F33: 2.1491 | G33: -0.003546
A34: A1 | B34: 1 | C34: =_xlfn.XLOOKUP(B34,Results!$B$23:$B$119,Results!$D$23:$D$119) | D34: 11 | E34: CHO | F34: 2.1526 | G34: -0.003455
A35: A1 | B35: 1 | C35: =_xlfn.XLOOKUP(B35,Results!$B$23:$B$119,Results!$D$23:$D$119) | D35: 12 | E35: CHO | F35: 2.156 | G35: -0.003372
... A1463: C12 | B1463: 36 | C1463: =_xlfn.XLOOKUP(B1463,Results!$B$23:$B$119,Results!$D$23:$D$119) | D1463: 40 | E1463: CHO | F1463: 7.0435 | G1463: 4.636298
A1464: D1 | B1464: 37 | C1464: =_xlfn.XLOOKUP(B1464,Results!$B$23:$B$119,Results!$D$23:$D$119) | D1464: 1
A1465: D1 | B1465: 37 | C1465: =_xlfn.XLOOKUP(B1465,Results!$B$23:$B$119,Results!$D$23:$D$119) | D1465: 2
A1466: D1 | B1466: 37 | C1466: =_xlfn.XLOOKUP(B1466,Results!$B$23:$B$119,Results!$D$23:$D$119) | D1466: 3
A1467: D1 | B1467: 37 | C1467: =_xlfn.XLOOKUP(B1467,Results!$B$23:$B$119,Results!$D$23:$D$119) | D1467: 4
A1468: D1 | B1468: 37 | C1468: =_xlfn.XLOOKUP(B1468,Results!$B$23:$B$119,Results!$D$23:$D$119) | D1468: 5
A1469: D1 | B1469: 37 | C1469: =_xlfn.XLOOKUP(B1469,Results!$B$23:$B$119,Results!$D$23:$D$119) | D1469: 6
A1470: D1 | B1470: 37 | C1470: =_xlfn.XLOOKUP(B1470,Results!$B$23:$B$119,Results!$D$23:$D$119) | D1470: 7
...

Sheet STD Curve
B1: Quantity | C1: Log(Conc) | D1: Ct
B2: 300 | C2: =LOG(B2) | D2: 13.2588
B3: 300 | C3: =LOG(B3) | D3: 13.1947
B4: 300 | C4: =LOG(B4) | D4: 13.138
B5: 30 | C5: =LOG(B5) | D5: 16.3923
B6: 30 | C6: =LOG(B6) | D6: 16.42
B7: 30 | C7: =LOG(B7) | D7: 16.4538
B8: 3 | C8: =LOG(B8) | D8: 19.6245
B9: 3 | C9: =LOG(B9) | D9: 19.7364
B10: 3 | C10: =LOG(B10) | D10: 19.7427
B11: 0.3 | C11: =LOG(B11) | D11: 22.9505
B12: 0.3 | C12: =LOG(B12) | D12: 23.0167
B13: 0.3 | C13: =LOG(B13) | D13: 23.0848
... B19: 0.003 | C19: =LOG(B19) | D19: 29.7917
F21: R2 | G21: Slope | H21: Y-Intercept | I21: Efficiency | J21: Ct Mean | K21: Ct SD | L21: LOD | M21: LOD Conc | N21: LOQ | O21: LOQ Conc | P21: Ct at LOQ
F22: =L26 | G22: =M26 | H22: =N26 | I22: =AE26 | J22: =G41 | K22: =I41 | L22: =3.3*K22/ABS(G22) | M22: =10^L22 | N22: =10*K22/ABS(G22) | O22: =10^N22 | P22: =G22*LOG10(O22)+H22
A25: Well | B25: Well Position | C25: Task | D25: Sample Name | E25: Target Name | F25: Ct | G25: Ct Mean | H25: Ct CV% | I25: Ct SD | J25: Quantity | K25: Dilution Factor | L25: R2 | M25: Slope | N25: Y-Intercept | O25: Total DNA per mL | P25: Flag | Q25: Ct Threshold | R25: Automatic Ct Threshold | S25: CQ Confidence | T25: Automatic Baseline | U25: Baseline Start | V25: Baseline End | W25: Spike Input | X25: Back calculated value | Y25: Back Calculation Mean | Z25: Back Calculation %CV | AA25: Back Calculation SD | AB25: Back Calculation % difference | AC25: Back Calculation % difference Mean | AD25: Fit | AE25: Amplification Efficiency | AF25: Amplification Status | AG25: AMPNC | AH25: NOAMP | AI25: EXPFAIL | AJ25: CQCONF | AL25: STD Replicate Ct %CV |<=5%| | AM25: R2 |>=99%| | AN25: Efficiency within 90-110% | AO25: Back Calculation %Diff |<=25%|
A26: A10 | B26: 10 | C26: STANDARD | D26: STD 300 | E26: CHO | F26: 13.2588 | G26: 13.1972 | H26: 0.46 | I26: 0.0605 | J26: 300 | K26: 1 | L26: 0.9998 | M26: -3.3008 | N26: 21.3153 | O26: 0 | P26: 0 | Q26: 0.207 | R26: true | S26: 1 | T26: Yes | U26: 3 | V26: 9 | W26: 0 | X26: 275.9091 | Y26: 288.2029 | Z26: 4.21 | AA26: 12.1357 | AB26: 8.03 | AC26: 3.9324 | AD26: Linear | AE26: 100.89 | AF26: Amplification | AG26: N | AH26: N | AI26: N | AJ26: N | AL26: =IF(H26<5,"PASS","FAIL") | AM26: =IF(L26>=0.99,"PASS","FAIL") | AN26: =IF(AND(AE26>=90,AE26<=110),"PASS","FAIL") | AO26: =IF(ABS(AB26)<=25,"PASS","FAIL")
A27: A11 | B27: 11 | C27: STANDARD | D27: STD 300 | E27: CHO | F27: 13.1947 | G27: 13.1972 | H27: 0.46 | I27: 0.0605 | J27: 300 | K27: 1 | L27: 0.9998 | M27: -3.3008 | N27: 21.3153 | O27: 0 | P27: 0 | Q27: 0.207 | R27: true | S27: 1 | T27: Yes | U27: 3 | V27: 9 | W27: 0 | X27: 288.5257 | Y27: 288.2029 | Z27: 4.21 | AA27: 12.1357 | AB27: 3.82 | AC27: 3.9324 | AD27: Linear | AE27: 100.89 | AF27: Amplification | AG27: N | AH27: N | AI27: N | AJ27: N | AL27: =IF(H27<5,"PASS","FAIL") | AM27: =IF(L27>=0.99,"PASS","FAIL") | AN27: =IF(AND(AE27>=90,AE27<=110),"PASS","FAIL") | AO27: =IF(ABS(AB27)<=25,"PASS","FAIL")
A28: A12 | B28: 12 | C28: STANDARD | D28: STD 300 | E28: CHO | F28: 13.138 | G28: 13.1972 | H28: 0.46 | I28: 0.0605 | J28: 300 | K28: 1 | L28: 0.9998 | M28: -3.3008 | N28: 21.3153 | O28: 0 | P28: 0 | Q28: 0.207 | R28: true | S28: 1 | T28: Yes | U28: 3 | V28: 8 | W28: 0 | X28: 300.174 | Y28: 288.2029 | Z28: 4.21 | AA28: 12.1357 | AB28: -0.06 | AC28: 3.9324 | AD28: Linear | AE28: 100.89 | AF28: Amplification | AG28: N | AH28: N | AI28: N | AJ28: N | AL28: =IF(H28<5,"PASS","FAIL") | AM28: =IF(L28>=0.99,"PASS","FAIL") | AN28: =IF(AND(AE28>=90,AE28<=110),"PASS","FAIL") | AO28: =IF(ABS(AB28)<=25,"PASS","FAIL")
A29: B10 | B29: 22 | C29: STANDARD | D29: STD 30 | E29: CHO | F29: 16.3923 | G29: 16.422 | H29: 0.19 | I29: 0.0308 | J29: 30 | K29: 1 | L29: 0.9998 | M29: -3.3008 | N29: 21.3153 | O29: 0 | P29: 0 | Q29: 0.207 | R29: true | S29: 1 | T29: Yes | U29: 3 | V29: 11 | W29: 0 | X29: 31.0077 | Y29: 30.3755 | Z29: 2.15 | AA29: 0.6525 | AB29: -3.36 | AC29: -1.2517 | AD29: Linear | AE29: 100.89 | AF29: Amplification | AG29: N | AH29: N | AI29: N | AJ29: N | AL29: =IF(H29<5,"PASS","FAIL") | AM29: =IF(L29>=0.99,"PASS","FAIL") | AN29: =IF(AND(AE29>=90,AE29<=110),"PASS","FAIL") | AO29: =IF(ABS(AB29)<=25,"PASS","FAIL")
A30: B11 | B30: 23 | C30: STANDARD | D30: STD 30 | E30: CHO | F30: 16.42 | G30: 16.422 | H30: 0.19 | I30: 0.0308 | J30: 30 | K30: 1 | L30: 0.9998 | M30: -3.3008 | N30: 21.3153 | O30: 0 | P30: 0 | Q30: 0.207 | R30: true | S30: 1 | T30: Yes | U30: 3 | V30: 11 | W30: 0 | X30: 30.4144 | Y30: 30.3755 | Z30: 2.15 | AA30: 0.6525 | AB30: -1.38 | AC30: -1.2517 | AD30: Linear | AE30: 100.89 | AF30: Amplification | AG30: N | AH30: N | AI30: N | AJ30: N | AL30: =IF(H30<5,"PASS","FAIL") | AM30: =IF(L30>=0.99,"PASS","FAIL") | AN30: =IF(AND(AE30>=90,AE30<=110),"PASS","FAIL") | AO30: =IF(ABS(AB30)<=25,"PASS","FAIL")
A31: B12 | B31: 24 | C31: STANDARD | D31: STD 30 | E31: CHO | F31: 16.4538 | G31: 16.422 | H31: 0.19 | I31: 0.0308 | J31: 30 | K31: 1 | L31: 0.9998 | M31: -3.3008 | N31: 21.3153 | O31: 0 | P31: 0 | Q31: 0.207 | R31: true | S31: 1 | T31: Yes | U31: 3 | V31: 11 | W31: 0 | X31: 29.7044 | Y31: 30.3755 | Z31: 2.15 | AA31: 0.6525 | AB31: 0.99 | AC31: -1.2517 | AD31: Linear | AE31: 100.89 | AF31: Amplification | AG31: N | AH31: N | AI31: N | AJ31: N | AL31: =IF(H31<5,"PASS","FAIL") | AM31: =IF(L31>=0.99,"PASS","FAIL") | AN31: =IF(AND(AE31>=90,AE31<=110),"PASS","FAIL") | AO31: =IF(ABS(AB31)<=25,"PASS","FAIL")
A32: C10 | B32: 34 | C32: STANDARD | D32: STD 3 | E32: CHO | F32: 19.6245 | G32: 19.7012 | H32: 0.34 | I32: 0.0665 | J32: 3 | K32: 1 | L32: 0.9998 | M32: -3.3008 | N32: 21.3153 | O32: 0 | P32: 0 | Q32: 0.207 | R32: true | S32: 1 | T32: Yes | U32: 3 | V32: 13 | W32: 0 | X32: 3.2526 | Y32: 3.0854 | Z32: 4.7 | AA32: 0.1449 | AB32: -8.42 | AC32: -2.8479 | AD32: Linear | AE32: 100.89 | AF32: Amplification | AG32: N | AH32: N | AI32: N | AJ32: N | AL32: =IF(H32<5,"PASS","FAIL") | AM32: =IF(L32>=0.99,"PASS","FAIL") | AN32: =IF(AND(AE32>=90,AE32<=110),"PASS","FAIL") | AO32: =IF(ABS(AB32)<=25,"PASS","FAIL")
A33: C11 | B33: 35 | C33: STANDARD | D33: STD 3 | E33: CHO | F33: 19.7364 | G33: 19.7012 | H33: 0.34 | I33: 0.0665 | J33: 3 | K33: 1 | L33: 0.9998 | M33: -3.3008 | N33: 21.3153 | O33: 0 | P33: 0 | Q33: 0.207 | R33: true | S33: 1 | T33: Yes | U33: 3 | V33: 15 | W33: 0 | X33: 3.0085 | Y33: 3.0854 | Z33: 4.7 | AA33: 0.1449 | AB33: -0.28 | AC33: -2.8479 | AD33: Linear | AE33: 100.89 | AF33: Amplification | AG33: N | AH33: N | AI33: N | AJ33: N | AL33: =IF(H33<5,"PASS","FAIL") | AM33: =IF(L33>=0.99,"PASS","FAIL") | AN33: =IF(AND(AE33>=90,AE33<=110),"PASS","FAIL") | AO33: =IF(ABS(AB33)<=25,"PASS","FAIL")
A34: C12 | B34: 36 | C34: STANDARD | D34: STD 3 | E34: CHO | F34: 19.7427 | G34: 19.7012 | H34: 0.34 | I34: 0.0665 | J34: 3 | K34: 1 | L34: 0.9998 | M34: -3.3008 | N34: 21.3153 | O34: 0 | P34: 0 | Q34: 0.207 | R34: true | S34: 1 | T34: Yes | U34: 3 | V34: 14 | W34: 0 | X34: 2.9952 | Y34: 3.0854 | Z34: 4.7 | AA34: 0.1449 | AB34: 0.16 | AC34: -2.8479 | AD34: Linear | AE34: 100.89 | AF34: Amplification | AG34: N | AH34: N | AI34: N | AJ34: N | AL34: =IF(H34<5,"PASS","FAIL") | AM34: =IF(L34>=0.99,"PASS","FAIL") | AN34: =IF(AND(AE34>=90,AE34<=110),"PASS","FAIL") | AO34: =IF(ABS(AB34)<=25,"PASS","FAIL")
A35: D10 | B35: 46 | C35: STANDARD | D35: STD 0.3 | E35: CHO | F35: 22.9505 | G35: 23.0173 | H35: 0.29 | I35: 0.0672 | J35: 0.3 | K35: 1 | L35: 0.9998 | M35: -3.3008 | N35: 21.3153 | O35: 0 | P35: 0 | Q35: 0.207 | R35: true | S35: 1 | T35: Yes | U35: 3 | V35: 17 | W35: 0 | X35: 0.3196 | Y35: 0.3053 | Z35: 4.68 | AA35: 0.0143 | AB35: -6.53 | AC35: -1.7549 | AD35: Linear | AE35: 100.89 | AF35: Amplification | AG35: N | AH35: N | AI35: N | AJ35: N | AL35: =IF(H35<5,"PASS","FAIL") | AM35: =IF(L35>=0.99,"PASS","FAIL") | AN35: =IF(AND(AE35>=90,AE35<=110),"PASS","FAIL") | AO35: =IF(ABS(AB35)<=25,"PASS","FAIL")
A36: D11 | B36: 47 | C36: STANDARD | D36: STD 0.3 | E36: CHO | F36: 23.0167 | G36: 23.0173 | H36: 0.29 | I36: 0.0672 | J36: 0.3 | K36: 1 | L36: 0.9998 | M36: -3.3008 | N36: 21.3153 | O36: 0 | P36: 0 | Q36: 0.207 | R36: true | S36: 1 | T36: Yes | U36: 3 | V36: 17 | W36: 0 | X36: 0.3052 | Y36: 0.3053 | Z36: 4.68 | AA36: 0.0143 | AB36: -1.73 | AC36: -1.7549 | AD36: Linear | AE36: 100.89 | AF36: Amplification | AG36: N | AH36: N | AI36: N | AJ36: N | AL36: =IF(H36<5,"PASS","FAIL") | AM36: =IF(L36>=0.99,"PASS","FAIL") | AN36: =IF(AND(AE36>=90,AE36<=110),"PASS","FAIL") | AO36: =IF(ABS(AB36)<=25,"PASS","FAIL")
A37: D12 | B37: 48 | C37: STANDARD | D37: STD 0.3 | E37: CHO | F37: 23.0848 | G37: 23.0173 | H37: 0.29 | I37: 0.0672 | J37: 0.3 | K37: 1 | L37: 0.9998 | M37: -3.3008 | N37: 21.3153 | O37: 0 | P37: 0 | Q37: 0.207 | R37: true | S37: 1 | T37: Yes | U37: 3 | V37: 18 | W37: 0 | X37: 0.291 | Y37: 0.3053 | Z37: 4.68 | AA37: 0.0143 | AB37: 2.99 | AC37: -1.7549 | AD37: Linear | AE37: 100.89 | AF37: Amplification | AG37: N | AH37: N | AI37: N | AJ37: N | AL37: =IF(H37<5,"PASS","FAIL") | AM37: =IF(L37>=0.99,"PASS","FAIL") | AN37: =IF(AND(AE37>=90,AE37<=110),"PASS","FAIL") | AO37: =IF(ABS(AB37)<=25,"PASS","FAIL")
... A43: F12 | B43: 72 | C43: STANDARD | D43: STD 0.003 | E43: CHO | F43: 29.7917 | G43: 29.7218 | H43: 0.47 | I43: 0.1389 | J43: 0.003 | K43: 1 | L43: 0.9998 | M43: -3.3008 | N43: 21.3153 | O43: 0 | P43: 0 | Q43: 0.207 | R43: true | S43: 1 | T43: Yes | U43: 3 | V43: 23 | W43: 0 | X43: 0.0027 | Y43: 0.0028 | Z43: 9.94 | AA43: 0.0003 | AB43: 9.86 | AC43: 5.0557 | AD43: Linear | AE43: 100.89 | AF43: Amplification | AG43: N | AH43: N | AI43: N | AJ43: N | AL43: =IF(H43<5,"PASS","FAIL") | AM43: =IF(L43>=0.99,"PASS","FAIL") | AN43: =IF(AND(AE43>=90,AE43<=110),"PASS","FAIL") | AO43: =IF(ABS(AB43)<=25,"PASS","FAIL")

Sheet NC
C6: *Note: Amplification in FB. Solution turned cloudy when LA was added before incubation. Suppect contamination.
F10: R2 | G10: Slope | H10: Y-Intercept | I10: Efficiency | J10: Ct Mean | K10: Ct SD | L10: LOD | M10: LOD Conc | N10: LOQ | O10: LOQ Conc | P10: Ct at LOQ
F11: 0.9998 | G11: -3.3008 | H11: 21.3153 | I11: 100.89 | J11: 29.7218 | K11: 0.1389 | L11: 0.13886634 | M11: 1.3767857 | N11: 0.42080708 | O11: 2.6351605 | P11: 19.9263
A14: Well | B14: Well Position | C14: Task | D14: Sample Name | E14: Target Name | F14: Ct | G14: Dilution Factor | H14: R2 | I14: Slope | J14: Y-Intercept | K14: Flag | L14: Ct Threshold | M14: Automatic Ct Threshold | N14: CQ Confidence | O14: Automatic Baseline | P14: Baseline Start | Q14: Baseline End | R14: Spike Input | S14: Fit | T14: Amplification Efficiency | U14: Amplification Status | V14: AMPNC | W14: NOAMP | X14: EXPFAIL | Y14: CQCONF | AA14: NEC Ct >= LOQ Ct | AB14: NTC Ct Undetermined
A15: A1 | B15: 1 | C15: NTC | D15: NTC | E15: CHO | F15: Undetermined | G15: 1 | H15: 0.9998 | I15: -3.3008 | J15: 21.3153 | K15: 0 | L15: 0.207 | M15: true | N15: 0 | O15: Yes | P15: 3 | Q15: 39 | R15: 0 | S15: Linear | T15: 100.89 | U15: No Amp | V15: N | W15: N | X15: N | Y15: N | AA15: =IF(F15 > $P$11,"PASS","FAIL") | AB15: =IF(F15="Undetermined","PASS","FAIL")
A16: A2 | B16: 2 | C16: NTC | D16: NTC | E16: CHO | F16: Undetermined | G16: 1 | H16: 0.9998 | I16: -3.3008 | J16: 21.3153 | K16: 0 | L16: 0.207 | M16: true | N16: 0 | O16: Yes | P16: 3 | Q16: 39 | R16: 0 | S16: Linear | T16: 100.89 | U16: No Amp | V16: N | W16: N | X16: N | Y16: N | AA16: =IF(F16 > $P$11,"PASS","FAIL") | AB16: =IF(F16="Undetermined","PASS","FAIL")
A17: A3 | B17: 3 | C17: NTC | D17: NTC | E17: CHO | F17: Undetermined | G17: 1 | H17: 0.9998 | I17: -3.3008 | J17: 21.3153 | K17: 0 | L17: 0.207 | M17: true | N17: 0 | O17: Yes | P17: 3 | Q17: 39 | R17: 0 | S17: Linear | T17: 100.89 | U17: No Amp | V17: N | W17: N | X17: N | Y17: N | AA17: =IF(F17 > $P$11,"PASS","FAIL") | AB17: =IF(F17="Undetermined","PASS","FAIL")
A18: B1 | B18: 13 | C18: NTC | D18: NEC - FB | E18: CHO | F18: 28.6104 | G18: 1 | H18: 0.9998 | I18: -3.3008 | J18: 21.3153 | K18: 1 | L18: 0.207 | M18: true | N18: 1 | O18: Yes | P18: 3 | Q18: 23 | R18: 0 | S18: Linear | T18: 100.89 | U18: Amplification | V18: Y | W18: N | X18: N | Y18: N | AA18: =IF(F18 > $P$11,"PASS","FAIL")
A19: B2 | B19: 14 | C19: NTC | D19: NEC - FB | E19: CHO | F19: 28.5299 | G19: 1 | H19: 0.9998 | I19: -3.3008 | J19: 21.3153 | K19: 1 | L19: 0.207 | M19: true | N19: 1 | O19: Yes | P19: 3 | Q19: 22 | R19: 0 | S19: Linear | T19: 100.89 | U19: Amplification | V19: Y | W19: N | X19: N | Y19: N | AA19: =IF(F19 > $P$11,"PASS","FAIL")
A20: B3 | B20: 15 | C20: NTC | D20: NEC - FB | E20: CHO | F20: 28.4455 | G20: 1 | H20: 0.9998 | I20: -3.3008 | J20: 21.3153 | K20: 1 | L20: 0.207 | M20: true | N20: 1 | O20: Yes | P20: 3 | Q20: 22 | R20: 0 | S20: Linear | T20: 100.89 | U20: Amplification | V20: Y | W20: N | X20: N | Y20: N | AA20: =IF(F20 > $P$11,"PASS","FAIL")
A21: C1 | B21: 25 | C21: NTC | D21: NEC - PBS | E21: CHO | F21: Undetermined | G21: 1 | H21: 0.9998 | I21: -3.3008 | J21: 21.3153 | K21: 0 | L21: 0.207 | M21: true | N21: 0 | O21: Yes | P21: 3 | Q21: 29 | R21: 0 | S21: Linear | T21: 100.89 | U21: No Amp | V21: N | W21: N | X21: N | Y21: N | AA21: =IF(F21 > $P$11,"PASS","FAIL")
A22: C2 | B22: 26 | C22: NTC | D22: NEC - PBS | E22: CHO | F22: 37.2977 | G22: 1 | H22: 0.9998 | I22: -3.3008 | J22: 21.3153 | K22: 0 | L22: 0.207 | M22: true | N22: 1 | O22: Yes | P22: 3 | Q22: 30 | R22: 0 | S22: Linear | T22: 100.89 | V22: N | W22: N | X22: N | Y22: N | AA22: =IF(F22 > $P$11,"PASS","FAIL")
A23: C3 | B23: 27 | C23: NTC | D23: NEC - PBS | E23: CHO | F23: 38.9558 | G23: 1 | H23: 0.9998 | I23: -3.3008 | J23: 21.3153 | K23: 0 | L23: 0.207 | M23: true | N23: 0 | O23: Yes | P23: 3 | Q23: 32 | R23: 0 | S23: Linear | T23: 100.89 | U23: No Amp | V23: N | W23: N | X23: N | Y23: N | AA23: =IF(F23 > $P$11,"PASS","FAIL")

Sheet PC
C4: Conclusion: | D4: Widen criteria for extraction recovery: 55% - 80%
F10: R2 | G10: Slope | H10: Y-Intercept | I10: Efficiency | J10: Ct Mean | K10: Ct SD | L10: LOD | M10: LOD Conc | N10: LOQ | O10: LOQ Conc | P10: Ct at LOQ
F11: 0.9998 | G11: -3.3008 | H11: 21.3153 | I11: 100.89 | J11: 29.7218 | K11: 0.1389 | L11: 0.13886634 | M11: 1.3767857 | N11: 0.42080708 | O11: 2.6351605 | P11: 19.9263
A14: Well | B14: Well Position | C14: Task | D14: Sample Name | E14: Target Name | F14: Ct | G14: Ct Mean | H14: Ct CV% | I14: Ct SD | J14: Quantity | K14: Quantity Mean | L14: Quantity SD | M14: Quantity %CV | N14: Dilution Factor | O14: Dilution Adjusted | P14: % Recovery | Q14: R2 | R14: Slope | S14: Y-Intercept | T14: Total DNA per mL | U14: Flag | V14: Ct Threshold | W14: Automatic Ct Threshold | X14: CQ Confidence | Y14: Automatic Baseline | Z14: Baseline Start | AA14: Baseline End | AB14: Reference | AC14: Reference Adjusted | AD14: Spike Input | AE14: Fit | AF14: Amplification Efficiency | AG14: Amplification Status | AH14: AMPNC | AI14: NOAMP | AJ14: EXPFAIL | AK14: CQCONF | AN14: %Recovery within 80 to 120% | AO14: Ct Replicate %CV |<=5%| | AP14: Quantity Replicate %CV |<=15%|
A15: A7 | B15: 7 | C15: UNKNOWN | D15: ERC - 60 | E15: CHO | F15: 15.9329 | G15: 15.9407 | H15: 0.28 | I15: 0.044 | J15: 42.7195 | K15: 42.5016 | L15: 1.2996 | M15: 3.06 | N15: 1 | O15: 42.5016 | P15: 70.84 | Q15: 0.9998 | R15: -3.3008 | S15: 21.3153 | T15: 42.5016 | U15: 0 | V15: 0.207 | W15: true | X15: 1 | Y15: Yes | Z15: 3 | AA15: 10 | AB15: 0 | AC15: 42.5016 | AD15: 60 | AE15: Linear | AF15: 100.89 | AG15: Amplification | AH15: N | AI15: N | AJ15: N | AK15: N | AN15: =IF(AND(P15>=80, P15<=120),"PASS","FAIL") | AO15: =IF(H15<5,"PASS","FAIL") | AP15: =IF(M15<=15,"PASS","FAIL")
A16: A8 | B16: 8 | C16: UNKNOWN | D16: ERC - 60 | E16: CHO | F16: 15.9881 | G16: 15.9407 | H16: 0.28 | I16: 0.044 | J16: 41.1069 | K16: 42.5016 | L16: 1.2996 | M16: 3.06 | N16: 1 | O16: 42.5016 | P16: 70.84 | Q16: 0.9998 | R16: -3.3008 | S16: 21.3153 | T16: 42.5016 | U16: 0 | V16: 0.207 | W16: true | X16: 1 | Y16: Yes | Z16: 3 | AA16: 11 | AB16: 0 | AC16: 42.5016 | AD16: 60 | AE16: Linear | AF16: 100.89 | AG16: Amplification | AH16: N | AI16: N | AJ16: N | AK16: N | AN16: =IF(AND(P16>=80, P16<=120),"PASS","FAIL") | AO16: =IF(H16<5,"PASS","FAIL") | AP16: =IF(M16<=15,"PASS","FAIL")
A17: A9 | B17: 9 | C17: UNKNOWN | D17: ERC - 60 | E17: CHO | F17: 15.9011 | G17: 15.9407 | H17: 0.28 | I17: 0.044 | J17: 43.6785 | K17: 42.5016 | L17: 1.2996 | M17: 3.06 | N17: 1 | O17: 42.5016 | P17: 70.84 | Q17: 0.9998 | R17: -3.3008 | S17: 21.3153 | T17: 42.5016 | U17: 0 | V17: 0.207 | W17: true | X17: 1 | Y17: Yes | Z17: 3 | AA17: 9 | AB17: 0 | AC17: 42.5016 | AD17: 60 | AE17: Linear | AF17: 100.89 | AG17: Amplification | AH17: N | AI17: N | AJ17: N | AK17: N | AN17: =IF(AND(P17>=80, P17<=120),"PASS","FAIL") | AO17: =IF(H17<5,"PASS","FAIL") | AP17: =IF(M17<=15,"PASS","FAIL")
A18: B7 | B18: 19 | C18: UNKNOWN | D18: ERC - 30 | E18: CHO | F18: 17.0421 | G18: 17.0158 | H18: 0.16 | I18: 0.0274 | J18: 19.7065 | K18: 20.0732 | L18: 0.3835 | M18: 1.91 | N18: 1 | O18: 20.0732 | P18: 66.91 | Q18: 0.9998 | R18: -3.3008 | S18: 21.3153 | T18: 20.0732 | U18: 0 | V18: 0.207 | W18: true | X18: 1 | Y18: Yes | Z18: 3 | AA18: 12 | AB18: 0 | AC18: 20.0732 | AD18: 30 | AE18: Linear | AF18: 100.89 | AG18: Amplification | AH18: N | AI18: N | AJ18: N | AK18: N | AN18: =IF(AND(P18>=80, P18<=120),"PASS","FAIL") | AO18: =IF(H18<5,"PASS","FAIL") | AP18: =IF(M18<=15,"PASS","FAIL")
A19: B8 | B19: 20 | C19: UNKNOWN | D19: ERC - 30 | E19: CHO | F19: 17.0179 | G19: 17.0158 | H19: 0.16 | I19: 0.0274 | J19: 20.0415 | K19: 20.0732 | L19: 0.3835 | M19: 1.91 | N19: 1 | O19: 20.0732 | P19: 66.91 | Q19: 0.9998 | R19: -3.3008 | S19: 21.3153 | T19: 20.0732 | U19: 0 | V19: 0.207 | W19: true | X19: 1 | Y19: Yes | Z19: 3 | AA19: 12 | AB19: 0 | AC19: 20.0732 | AD19: 30 | AE19: Linear | AF19: 100.89 | AG19: Amplification | AH19: N | AI19: N | AJ19: N | AK19: N | AN19: =IF(AND(P19>=80, P19<=120),"PASS","FAIL") | AO19: =IF(H19<5,"PASS","FAIL") | AP19: =IF(M19<=15,"PASS","FAIL")
A20: B9 | B20: 21 | C20: UNKNOWN | D20: ERC - 30 | E20: CHO | F20: 16.9875 | G20: 17.0158 | H20: 0.16 | I20: 0.0274 | J20: 20.4716 | K20: 20.0732 | L20: 0.3835 | M20: 1.91 | N20: 1 | O20: 20.0732 | P20: 66.91 | Q20: 0.9998 | R20: -3.3008 | S20: 21.3153 | T20: 20.0732 | U20: 0 | V20: 0.207 | W20: true | X20: 1 | Y20: Yes | Z20: 3 | AA20: 12 | AB20: 0 | AC20: 20.0732 | AD20: 30 | AE20: Linear | AF20: 100.89 | AG20: Amplification | AH20: N | AI20: N | AJ20: N | AK20: N | AN20: =IF(AND(P20>=80, P20<=120),"PASS","FAIL") | AO20: =IF(H20<5,"PASS","FAIL") | AP20: =IF(M20<=15,"PASS","FAIL")
A21: C7 | B21: 31 | C21: UNKNOWN | D21: ERC - 10 | E21: CHO | F21: 18.5377 | G21: 18.5552 | H21: 0.09 | I21: 0.016 | J21: 6.9419 | K21: 6.8583 | L21: 0.0769 | M21: 1.12 | N21: 1 | O21: 6.8583 | P21: 68.58 | Q21: 0.9998 | R21: -3.3008 | S21: 21.3153 | T21: 6.8583 | U21: 0 | V21: 0.207 | W21: true | X21: 1 | Y21: Yes | Z21: 3 | AA21: 13 | AB21: 0 | AC21: 6.8583 | AD21: 10 | AE21: Linear | AF21: 100.89 | AG21: Amplification | AH21: N | AI21: N | AJ21: N | AK21: N | AN21: =IF(AND(P21>=80, P21<=120),"PASS","FAIL") | AO21: =IF(H21<5,"PASS","FAIL") | AP21: =IF(M21<=15,"PASS","FAIL")
A22: C8 | B22: 32 | C22: UNKNOWN | D22: ERC - 10 | E22: CHO | F22: 18.5584 | G22: 18.5552 | H22: 0.09 | I22: 0.016 | J22: 6.8424 | K22: 6.8583 | L22: 0.0769 | M22: 1.12 | N22: 1 | O22: 6.8583 | P22: 68.58 | Q22: 0.9998 | R22: -3.3008 | S22: 21.3153 | T22: 6.8583 | U22: 0 | V22: 0.207 | W22: true | X22: 1 | Y22: Yes | Z22: 3 | AA22: 13 | AB22: 0 | AC22: 6.8583 | AD22: 10 | AE22: Linear | AF22: 100.89 | AG22: Amplification | AH22: N | AI22: N | AJ22: N | AK22: N | AN22: =IF(AND(P22>=80, P22<=120),"PASS","FAIL") | AO22: =IF(H22<5,"PASS","FAIL") | AP22: =IF(M22<=15,"PASS","FAIL")
A23: C9 | B23: 33 | C23: UNKNOWN | D23: ERC - 10 | E23: CHO | F23: 18.5693 | G23: 18.5552 | H23: 0.09 | I23: 0.016 | J23: 6.7907 | K23: 6.8583 | L23: 0.0769 | M23: 1.12 | N23: 1 | O23: 6.8583 | P23: 68.58 | Q23: 0.9998 | R23: -3.3008 | S23: 21.3153 | T23: 6.8583 | U23: 0 | V23: 0.207 | W23: true | X23: 1 | Y23: Yes | Z23: 3 | AA23: 13 | AB23: 0 | AC23: 6.8583 | AD23: 10 | AE23: Linear | AF23: 100.89 | AG23: Amplification | AH23: N | AI23: N | AJ23: N | AK23: N | AN23: =IF(AND(P23>=80, P23<=120),"PASS","FAIL") | AO23: =IF(H23<5,"PASS","FAIL") | AP23: =IF(M23<=15,"PASS","FAIL")
A24: E1 | B24: 49 | C24: UNKNOWN | D24: HPC - 190 | E24: CHO | F24: 13.7174 | G24: 13.6248 | H24: 1.05 | I24: 0.1432 | J24: 200.3741 | K24: 214.4659 | L24: 21.9958 | M24: 10.26 | N24: 1 | O24: 214.4659 | P24: 112.88 | Q24: 0.9998 | R24: -3.3008 | S24: 21.3153 | T24: 214.4659 | U24: 0 | V24: 0.207 | W24: true | X24: 1 | Y24: Yes | Z24: 3 | AA24: 9 | AB24: 0 | AC24: 214.4659 | AD24: 189.9937 | AE24: Linear | AF24: 100.89 | AG24: Amplification | AH24: N | AI24: N | AJ24: N | AK24: N | AN24: =IF(AND(P24>=80, P24<=120),"PASS","FAIL") | AO24: =IF(H24<5,"PASS","FAIL") | AP24: =IF(M24<=15,"PASS","FAIL")
A25: E2 | B25: 50 | C25: UNKNOWN | D25: HPC - 190 | E25: CHO | F25: 13.6972 | G25: 13.6248 | H25: 1.05 | I25: 0.1432 | J25: 203.212 | K25: 214.4659 | L25: 21.9958 | M25: 10.26 | N25: 1 | O25: 214.4659 | P25: 112.88 | Q25: 0.9998 | R25: -3.3008 | S25: 21.3153 | T25: 214.4659 | U25: 0 | V25: 0.207 | W25: true | X25: 1 | Y25: Yes | Z25: 3 | AA25: 9 | AB25: 0 | AC25: 214.4659 | AD25: 189.9937 | AE25: Linear | AF25: 100.89 | AG25: Amplification | AH25: N | AI25: N | AJ25: N | AK25: N | AN25: =IF(AND(P25>=80, P25<=120),"PASS","FAIL") | AO25: =IF(H25<5,"PASS","FAIL") | AP25: =IF(M25<=15,"PASS","FAIL")
A26: E3 | B26: 51 | C26: UNKNOWN | D26: HPC - 190 | E26: CHO | F26: 13.4598 | G26: 13.6248 | H26: 1.05 | I26: 0.1432 | J26: 239.8116 | K26: 214.4659 | L26: 21.9958 | M26: 10.26 | N26: 1 | O26: 214.4659 | P26: 112.88 | Q26: 0.9998 | R26: -3.3008 | S26: 21.3153 | T26: 214.4659 | U26: 0 | V26: 0.207 | W26: true | X26: 1 | Y26: Yes | Z26: 3 | AA26: 7 | AB26: 0 | AC26: 214.4659 | AD26: 189.9937 | AE26: Linear | AF26: 100.89 | AG26: Amplification | AH26: N | AI26: N | AJ26: N | AK26: N | AN26: =IF(AND(P26>=80, P26<=120),"PASS","FAIL") | AO26: =IF(H26<5,"PASS","FAIL") | AP26: =IF(M26<=15,"PASS","FAIL")
... A32: G3 | B32: 75 | C32: UNKNOWN | D32: LPC - 5 | E32: CHO | F32: 18.8743 | G32: 18.8759 | H32: 0.05 | I32: 0.0101 | J32: 5.4892 | K32: 5.4834 | L32: 0.0384 | M32: 0.7 | N32: 1 | O32: 5.4834 | P32: 109.67 | Q32: 0.9998 | R32: -3.3008 | S32: 21.3153 | T32: 5.4834 | U32: 0 | V32: 0.207 | W32: true | X32: 1 | Y32: Yes | Z32: 3 | AA32: 14 | AB32: 0 | AC32: 5.4834 | AD32: 5 | AE32: Linear | AF32: 100.89 | AG32: Amplification | AH32: N | AI32: N | AJ32: N | AK32: N | AN32: =IF(AND(P32>=80, P32<=120),"PASS","FAIL") | AO32: =IF(H32<5,"PASS","FAIL") | AP32: =IF(M32<=15,"PASS","FAIL")

Sheet S1
B2: Criteria
B3: DNA/Protein = 15 ng/mg
I6: Sample Below LOQ
B7: Result Summary:
C8: Dilutional Linearity acceptable from Neat - 10x | I8: S1 = ~0.0004 ng/mL total DNA in unspiked sample
C9: Spike Recovery acceptable from Neat - 10x | I9: S1 = ~0.0002 ng/mg DNA/Protein
C10: Undetermined Ct from 100x to 1000x dilution | I10: S1 S = 3.2 ng/mL total DNA in spiked sample
B13: Validation
C14: Dilutions starting from Neat, 10x
C16: Spiked at 3 pg/uL
F20: Reference Dilution | H20: =N23 | T20: *ng/mL
A22: Well | B22: Well Position | C22: Task | D22: Sample Name | E22: Target Name | F22: Ct | G22: Ct Mean | H22: Ct CV% | I22: Ct SD | J22: Quantity | K22: Quantity Mean | L22: Quantity SD | M22: Quantity %CV | N22: Dilution Factor | O22: Dilution Adjusted | P22: % Recovery | Q22: R2 | R22: Slope | S22: Y-Intercept | T22: Total DNA per mL | U22: Total DNA per Protein Concentration | V22: Flag | W22: Ct Threshold | X22: Automatic Ct Threshold | Y22: CQ Confidence | Z22: Automatic Baseline | AA22: Baseline Start | AB22: Baseline End | AC22: Reference | AD22: Reference Adjusted | AE22: Spike Input | AF22: Fit | AG22: Amplification Efficiency | AH22: Amplification Status | AI22: AMPNC | AJ22: NOAMP | AK22: EXPFAIL | AL22: Protein Concentration | AM22: CQCONF | AP22: % Bias |20%| | AQ22: Dilutional Linearity |20%| | AR22: Ct Replicate %CV |<=5%| | AS22: Quantity Replicate %CV |<=15%|
A23: A4 | B23: 4 | C23: UNKNOWN | D23: S1 D1 | E23: CHO | F23: 32.3647 | G23: 32.5183 | H23: 0.81 | I23: 0.2622 | J23: 0.0004 | K23: 0.0004 | L23: 0.0001 | M23: 17.24 | N23: 1 | O23: 0.0004 | Q23: 0.9998 | R23: -3.3008 | S23: 21.3153 | T23: 0.0004 | U23: 0.0002 | V23: 0 | W23: 0.207 | X23: true | Y23: 1 | Z23: Yes | AA23: 3 | AB23: 27 | AC23: 0 | AD23: 0.0004 | AE23: 0 | AF23: Linear | AG23: 100.89 | AH23: Amplification | AI23: N | AJ23: N | AK23: N | AL23: 1.825 | AM23: N | AP23: =100*(O23-$O$23)/$O$23 | AQ23: =IF(ABS(AP23)<=20,"PASS","FAIL") | AR23: =IF(H23<=5,"PASS","FAIL") | AS23: =IF(M23<=15,"PASS","FAIL")
A24: A5 | B24: 5 | C24: UNKNOWN | D24: S1 D1 | E24: CHO | F24: 32.3692 | G24: 32.5183 | H24: 0.81 | I24: 0.2622 | J24: 0.0004 | K24: 0.0004 | L24: 0.0001 | M24: 17.24 | N24: 1 | O24: 0.0004 | Q24: 0.9998 | R24: -3.3008 | S24: 21.3153 | T24: 0.0004 | U24: 0.0002 | V24: 0 | W24: 0.207 | X24: true | Y24: 1 | Z24: Yes | AA24: 3 | AB24: 28 | AC24: 0 | AD24: 0.0004 | AE24: 0 | AF24: Linear | AG24: 100.89 | AH24: Amplification | AI24: N | AJ24: N | AK24: N | AL24: 1.825 | AM24: N | AP24: =100*(O24-$O$23)/$O$23 | AQ24: =IF(ABS(AP24)<=20,"PASS","FAIL") | AR24: =IF(H24<=5,"PASS","FAIL") | AS24: =IF(M24<=15,"PASS","FAIL")
A25: A6 | B25: 6 | C25: UNKNOWN | D25: S1 D1 | E25: CHO | F25: 32.8211 | G25: 32.5183 | H25: 0.81 | I25: 0.2622 | J25: 0.0003 | K25: 0.0004 | L25: 0.0001 | M25: 17.24 | N25: 1 | O25: 0.0004 | Q25: 0.9998 | R25: -3.3008 | S25: 21.3153 | T25: 0.0004 | U25: 0.0002 | V25: 0 | W25: 0.207 | X25: true | Y25: 1 | Z25: Yes | AA25: 3 | AB25: 26 | AC25: 0 | AD25: 0.0004 | AE25: 0 | AF25: Linear | AG25: 100.89 | AH25: Amplification | AI25: N | AJ25: N | AK25: N | AL25: 1.825 | AM25: N | AP25: =100*(O25-$O$23)/$O$23 | AQ25: =IF(ABS(AP25)<=20,"PASS","FAIL") | AR25: =IF(H25<=5,"PASS","FAIL") | AS25: =IF(M25<=15,"PASS","FAIL")
A26: B4 | B26: 16 | C26: UNKNOWN | D26: S1 D2 | E26: CHO | F26: 35.7364 | G26: 35.8319 | H26: 0.91 | I26: 0.3254 | J26: 0 | K26: 0 | L26: 0 | M26: 21.52 | N26: 10 | O26: 0.0004 | Q26: 0.9998 | R26: -3.3008 | S26: 21.3153 | T26: 0.0004 | U26: 0.0002 | V26: 0 | W26: 0.207 | X26: true | Y26: 1 | Z26: Yes | AA26: 3 | AB26: 30 | AC26: 0 | AD26: 0 | AE26: 0 | AF26: Linear | AG26: 100.89 | AH26: Amplification | AI26: N | AJ26: N | AK26: N | AL26: 1.825 | AM26: N | AP26: =100*(O26-$O$23)/$O$23 | AQ26: =IF(ABS(AP26)<=20,"PASS","FAIL") | AR26: =IF(H26<=5,"PASS","FAIL") | AS26: =IF(M26<=15,"PASS","FAIL")
A27: B5 | B27: 17 | C27: UNKNOWN | D27: S1 D2 | E27: CHO | F27: 35.5648 | G27: 35.8319 | H27: 0.91 | I27: 0.3254 | J27: 0 | K27: 0 | L27: 0 | M27: 21.52 | N27: 10 | O27: 0.0004 | Q27: 0.9998 | R27: -3.3008 | S27: 21.3153 | T27: 0.0004 | U27: 0.0002 | V27: 0 | W27: 0.207 | X27: true | Y27: 1 | Z27: Yes | AA27: 3 | AB27: 30 | AC27: 0 | AD27: 0 | AE27: 0 | AF27: Linear | AG27: 100.89 | AH27: Amplification | AI27: N | AJ27: N | AK27: N | AL27: 1.825 | AM27: N | AP27: =100*(O27-$O$23)/$O$23 | AQ27: =IF(ABS(AP27)<=20,"PASS","FAIL") | AR27: =IF(H27<=5,"PASS","FAIL") | AS27: =IF(M27<=15,"PASS","FAIL")
A28: B6 | B28: 18 | C28: UNKNOWN | D28: S1 D2 | E28: CHO | F28: 36.1944 | G28: 35.8319 | H28: 0.91 | I28: 0.3254 | J28: 0 | K28: 0 | L28: 0 | M28: 21.52 | N28: 10 | O28: 0.0004 | Q28: 0.9998 | R28: -3.3008 | S28: 21.3153 | T28: 0.0004 | U28: 0.0002 | V28: 0 | W28: 0.207 | X28: true | Y28: 1 | Z28: Yes | AA28: 3 | AB28: 30 | AC28: 0 | AD28: 0 | AE28: 0 | AF28: Linear | AG28: 100.89 | AH28: Amplification | AI28: N | AJ28: N | AK28: N | AL28: 1.825 | AM28: N | AP28: =100*(O28-$O$23)/$O$23 | AQ28: =IF(ABS(AP28)<=20,"PASS","FAIL") | AR28: =IF(H28<=5,"PASS","FAIL") | AS28: =IF(M28<=15,"PASS","FAIL")
A29: C4 | B29: 28 | C29: UNKNOWN | D29: S1 D3 | E29: CHO | F29: Undetermined | N29: 100 | Q29: 0.9998 | R29: -3.3008 | S29: 21.3153 | T29: 0.0007 | U29: 0.0004 | V29: 1 | W29: 0.207 | X29: true | Y29: 0 | Z29: Yes | AA29: 3 | AB29: 35 | AC29: 0 | AE29: 0 | AF29: Linear | AG29: 100.89 | AH29: No Amp | AI29: N | AJ29: N | AK29: N | AL29: 1.825 | AM29: Y | AP29: =100*(O29-$O$23)/$O$23 | AQ29: =IF(ABS(AP29)<=20,"PASS","FAIL") | AR29: =IF(H29<=5,"PASS","FAIL") | AS29: =IF(M29<=15,"PASS","FAIL")
A30: C5 | B30: 29 | C30: UNKNOWN | D30: S1 D3 | E30: CHO | F30: 38.3456 | G30: 38.3456 | J30: 0 | K30: 0 | N30: 100 | O30: 0.0007 | Q30: 0.9998 | R30: -3.3008 | S30: 21.3153 | T30: 0.0007 | U30: 0.0004 | V30: 1 | W30: 0.207 | X30: true | Y30: 0 | Z30: Yes | AA30: 3 | AB30: 33 | AC30: 0 | AD30: 0 | AE30: 0 | AF30: Linear | AG30: 100.89 | AH30: Amplification | AI30: N | AJ30: N | AK30: N | AL30: 1.825 | AM30: Y | AP30: =100*(O30-$O$23)/$O$23 | AQ30: =IF(ABS(AP30)<=20,"PASS","FAIL") | AR30: =IF(H30<=5,"PASS","FAIL") | AS30: =IF(M30<=15,"PASS","FAIL")
A31: C6 | B31: 30 | C31: UNKNOWN | D31: S1 D3 | E31: CHO | F31: Undetermined | N31: 100 | Q31: 0.9998 | R31: -3.3008 | S31: 21.3153 | T31: 0.0007 | U31: 0.0004 | V31: 3 | W31: 0.207 | X31: true | Y31: 0 | Z31: Yes | AA31: 3 | AB31: 39 | AC31: 0 | AE31: 0 | AF31: Linear | AG31: 100.89 | AH31: No Amp | AI31: N | AJ31: Y | AK31: Y | AL31: 1.825 | AM31: Y | AP31: =100*(O31-$O$23)/$O$23 | AQ31: =IF(ABS(AP31)<=20,"PASS","FAIL") | AR31: =IF(H31<=5,"PASS","FAIL") | AS31: =IF(M31<=15,"PASS","FAIL")
A32: D4 | B32: 40 | C32: UNKNOWN | D32: S1 D4 | E32: CHO | F32: Undetermined | N32: 1000 | Q32: 0.9998 | R32: -3.3008 | S32: 21.3153 | T32: 0 | U32: 0 | V32: 3 | W32: 0.207 | X32: true | Y32: 0 | Z32: Yes | AA32: 3 | AB32: 39 | AC32: 0 | AE32: 0 | AF32: Linear | AG32: 100.89 | AH32: No Amp | AI32: N | AJ32: Y | AK32: Y | AL32: 1.825 | AM32: Y | AP32: =100*(O32-$O$23)/$O$23 | AQ32: =IF(ABS(AP32)<=20,"PASS","FAIL") | AR32: =IF(H32<=5,"PASS","FAIL") | AS32: =IF(M32<=15,"PASS","FAIL")
A33: D5 | B33: 41 | C33: UNKNOWN | D33: S1 D4 | E33: CHO | F33: Undetermined | N33: 1000 | Q33: 0.9998 | R33: -3.3008 | S33: 21.3153 | T33: 0 | U33: 0 | V33: 1 | W33: 0.207 | X33: true | Y33: 0 | Z33: Yes | AA33: 3 | AB33: 35 | AC33: 0 | AE33: 0 | AF33: Linear | AG33: 100.89 | AH33: No Amp | AI33: N | AJ33: N | AK33: N | AL33: 1.825 | AM33: Y | AP33: =100*(O33-$O$23)/$O$23 | AQ33: =IF(ABS(AP33)<=20,"PASS","FAIL") | AR33: =IF(H33<=5,"PASS","FAIL") | AS33: =IF(M33<=15,"PASS","FAIL")
A34: D6 | B34: 42 | C34: UNKNOWN | D34: S1 D4 | E34: CHO | F34: Undetermined | N34: 1000 | Q34: 0.9998 | R34: -3.3008 | S34: 21.3153 | T34: 0 | U34: 0 | V34: 3 | W34: 0.207 | X34: true | Y34: 0 | Z34: Yes | AA34: 3 | AB34: 39 | AC34: 0 | AE34: 0 | AF34: Linear | AG34: 100.89 | AH34: No Amp | AI34: N | AJ34: Y | AK34: Y | AL34: 1.825 | AM34: Y | AP34: =100*(O34-$O$23)/$O$23 | AQ34: =IF(ABS(AP34)<=20,"PASS","FAIL") | AR34: =IF(H34<=5,"PASS","FAIL") | AS34: =IF(M34<=15,"PASS","FAIL")
AP37: Spike %Recovery | AQ37: Spike Recovery within 80-120%
A38: E4 | B38: 52 | C38: UNKNOWN | D38: S1 D1 S | E38: CHO | F38: 19.6437 | G38: 19.6189 | H38: 0.21 | I38: 0.0412 | J38: 3.2094 | K38: 3.2664 | L38: 0.0947 | M38: 2.9 | N38: 1 | O38: 3.2664 | P38: 108.88 | Q38: 0.9998 | R38: -3.3008 | S38: 21.3153 | T38: 3.2664 | V38: 0 | W38: 0.207 | X38: true | Y38: 1 | Z38: Yes | AA38: 3 | AB38: 14 | AC38: 0 | AD38: 3.2664 | AE38: 3 | AF38: Linear | AG38: 100.89 | AH38: Amplification | AI38: N | AJ38: N | AK38: N | AM38: N | AP38: =(100*(K38-K23))/AE38 | AQ38: =IF(AND(AP38>=80,AP38<=120),"PASS","FAIL")
A39: E5 | B39: 53 | C39: UNKNOWN | D39: S1 D1 S | E39: CHO | F39: 19.5713 | G39: 19.6189 | H39: 0.21 | I39: 0.0412 | J39: 3.3757 | K39: 3.2664 | L39: 0.0947 | M39: 2.9 | N39: 1 | O39: 3.2664 | P39: 108.88 | Q39: 0.9998 | R39: -3.3008 | S39: 21.3153 | T39: 3.2664 | V39: 0 | W39: 0.207 | X39: true | Y39: 1 | Z39: Yes | AA39: 3 | AB39: 14 | AC39: 0 | AD39: 3.2664 | AE39: 3 | AF39: Linear | AG39: 100.89 | AH39: Amplification | AI39: N | AJ39: N | AK39: N | AM39: N | AP39: =(100*(K39-K24))/AE39 | AQ39: =IF(AND(AP39>=80,AP39<=120),"PASS","FAIL")
A40: E6 | B40: 54 | C40: UNKNOWN | D40: S1 D1 S | E40: CHO | F40: 19.6417 | G40: 19.6189 | H40: 0.21 | I40: 0.0412 | J40: 3.214 | K40: 3.2664 | L40: 0.0947 | M40: 2.9 | N40: 1 | O40: 3.2664 | P40: 108.88 | Q40: 0.9998 | R40: -3.3008 | S40: 21.3153 | T40: 3.2664 | V40: 0 | W40: 0.207 | X40: true | Y40: 1 | Z40: Yes | AA40: 3 | AB40: 15 | AC40: 0 | AD40: 3.2664 | AE40: 3 | AF40: Linear | AG40: 100.89 | AH40: Amplification | AI40: N | AJ40: N | AK40: N | AM40: N | AP40: =(100*(K40-K25))/AE40 | AQ40: =IF(AND(AP40>=80,AP40<=120),"PASS","FAIL")
A41: F4 | B41: 64 | C41: UNKNOWN | D41: S1 D2 S | E41: CHO | F41: 19.6439 | G41: 19.6749 | H41: 0.2 | I41: 0.0389 | J41: 3.2089 | K41: 3.1411 | L41: 0.0846 | M41: 2.69 | N41: 1 | O41: 3.1411 | P41: 104.7 | Q41: 0.9998 | R41: -3.3008 | S41: 21.3153 | T41: 3.1411 | V41: 0 | W41: 0.207 | X41: true | Y41: 1 | Z41: Yes | AA41: 3 | AB41: 14 | AC41: 0 | AD41: 3.1411 | AE41: 3 | AF41: Linear | AG41: 100.89 | AH41: Amplification | AI41: N | AJ41: N | AK41: N | AM41: N | AP41: =(100*(K41-K26))/AE41 | AQ41: =IF(AND(AP41>=80,AP41<=120),"PASS","FAIL")
A42: F5 | B42: 65 | C42: UNKNOWN | D42: S1 D2 S | E42: CHO | F42: 19.6622 | G42: 19.6749 | H42: 0.2 | I42: 0.0389 | J42: 3.1682 | K42: 3.1411 | L42: 0.0846 | M42: 2.69 | N42: 1 | O42: 3.1411 | P42: 104.7 | Q42: 0.9998 | R42: -3.3008 | S42: 21.3153 | T42: 3.1411 | V42: 0 | W42: 0.207 | X42: true | Y42: 1 | Z42: Yes | AA42: 3 | AB42: 15 | AC42: 0 | AD42: 3.1411 | AE42: 3 | AF42: Linear | AG42: 100.89 | AH42: Amplification | AI42: N | AJ42: N | AK42: N | AM42: N | AP42: =(100*(K42-K27))/AE42 | AQ42: =IF(AND(AP42>=80,AP42<=120),"PASS","FAIL")
A43: F6 | B43: 66 | C43: UNKNOWN | D43: S1 D2 S | E43: CHO | F43: 19.7185 | G43: 19.6749 | H43: 0.2 | I43: 0.0389 | J43: 3.0462 | K43: 3.1411 | L43: 0.0846 | M43: 2.69 | N43: 1 | O43: 3.1411 | P43: 104.7 | Q43: 0.9998 | R43: -3.3008 | S43: 21.3153 | T43: 3.1411 | V43: 0 | W43: 0.207 | X43: true | Y43: 1 | Z43: Yes | AA43: 3 | AB43: 14 | AC43: 0 | AD43: 3.1411 | AE43: 3 | AF43: Linear | AG43: 100.89 | AH43: Amplification | AI43: N | AJ43: N | AK43: N | AM43: N | AP43: =(100*(K43-K28))/AE43 | AQ43: =IF(AND(AP43>=80,AP43<=120),"PASS","FAIL")
A44: G4 | B44: 76 | C44: UNKNOWN | D44: S1 D3 S | E44: CHO | F44: 19.68 | G44: 19.6959 | H44: 0.12 | I44: 0.0241 | J44: 3.1292 | K44: 3.095 | L44: 0.0517 | M44: 1.67 | N44: 1 | O44: 3.095 | P44: 103.17 | Q44: 0.9998 | R44: -3.3008 | S44: 21.3153 | T44: 3.095 | V44: 0 | W44: 0.207 | X44: true | Y44: 1 | Z44: Yes | AA44: 3 | AB44: 14 | AC44: 0 | AD44: 3.095 | AE44: 3 | AF44: Linear | AG44: 100.89 | AH44: Amplification | AI44: N | AJ44: N | AK44: N | AM44: N | AP44: =(100*(K44-K29))/AE44 | AQ44: =IF(AND(AP44>=80,AP44<=120),"PASS","FAIL")
A45: G5 | B45: 77 | C45: UNKNOWN | D45: S1 D3 S | E45: CHO | F45: 19.7236 | G45: 19.6959 | H45: 0.12 | I45: 0.0241 | J45: 3.0355 | K45: 3.095 | L45: 0.0517 | M45: 1.67 | N45: 1 | O45: 3.095 | P45: 103.17 | Q45: 0.9998 | R45: -3.3008 | S45: 21.3153 | T45: 3.095 | V45: 0 | W45: 0.207 | X45: true | Y45: 1 | Z45: Yes | AA45: 3 | AB45: 14 | AC45: 0 | AD45: 3.095 | AE45: 3 | AF45: Linear | AG45: 100.89 | AH45: Amplification | AI45: N | AJ45: N | AK45: N | AM45: N | AP45: =(100*(K45-K30))/AE45 | AQ45: =IF(AND(AP45>=80,AP45<=120),"PASS","FAIL")
A46: G6 | B46: 78 | C46: UNKNOWN | D46: S1 D3 S | E46: CHO | F46: 19.6841 | G46: 19.6959 | H46: 0.12 | I46: 0.0241 | J46: 3.1202 | K46: 3.095 | L46: 0.0517 | M46: 1.67 | N46: 1 | O46: 3.095 | P46: 103.17 | Q46: 0.9998 | R46: -3.3008 | S46: 21.3153 | T46: 3.095 | V46: 0 | W46: 0.207 | X46: true | Y46: 1 | Z46: Yes | AA46: 3 | AB46: 15 | AC46: 0 | AD46: 3.095 | AE46: 3 | AF46: Linear | AG46: 100.89 | AH46: Amplification | AI46: N | AJ46: N | AK46: N | AM46: N | AP46: =(100*(K46-K31))/AE46 | AQ46: =IF(AND(AP46>=80,AP46<=120),"PASS","FAIL")
A47: H4 | B47: 88 | C47: UNKNOWN | D47: S1 D4 S | E47: CHO | F47: 19.6611 | G47: 19.7067 | H47: 0.22 | I47: 0.0424 | J47: 3.1707 | K47: 3.0723 | L47: 0.0912 | M47: 2.97 | N47: 1 | O47: 3.0723 | P47: 102.41 | Q47: 0.9998 | R47: -3.3008 | S47: 21.3153 | T47: 3.0723 | V47: 0 | W47: 0.207 | X47: true | Y47: 1 | Z47: Yes | AA47: 3 | AB47: 14 | AC47: 0 | AD47: 3.0723 | AE47: 3 | AF47: Linear | AG47: 100.89 | AH47: Amplification | AI47: N | AJ47: N | AK47: N | AM47: N | AP47: =(100*(K47-K32))/AE47 | AQ47: =IF(AND(AP47>=80,AP47<=120),"PASS","FAIL")
A48: H5 | B48: 89 | C48: UNKNOWN | D48: S1 D4 S | E48: CHO | F48: 19.7449 | G48: 19.7067 | H48: 0.22 | I48: 0.0424 | J48: 2.9907 | K48: 3.0723 | L48: 0.0912 | M48: 2.97 | N48: 1 | O48: 3.0723 | P48: 102.41 | Q48: 0.9998 | R48: -3.3008 | S48: 21.3153 | T48: 3.0723 | V48: 0 | W48: 0.207 | X48: true | Y48: 1 | Z48: Yes | AA48: 3 | AB48: 15 | AC48: 0 | AD48: 3.0723 | AE48: 3 | AF48: Linear | AG48: 100.89 | AH48: Amplification | AI48: N | AJ48: N | AK48: N | AM48: N | AP48: =(100*(K48-K33))/AE48 | AQ48: =IF(AND(AP48>=80,AP48<=120),"PASS","FAIL")
A49: H6 | B49: 90 | C49: UNKNOWN | D49: S1 D4 S | E49: CHO | F49: 19.7142 | G49: 19.7067 | H49: 0.22 | I49: 0.0424 | J49: 3.0555 | K49: 3.0723 | L49: 0.0912 | M49: 2.97 | N49: 1 | O49: 3.0723 | P49: 102.41 | Q49: 0.9998 | R49: -3.3008 | S49: 21.3153 | T49: 3.0723 | V49: 0 | W49: 0.207 | X49: true | Y49: 1 | Z49: Yes | AA49: 3 | AB49: 15 | AC49: 0 | AD49: 3.0723 | AE49: 3 | AF49: Linear | AG49: 100.89 | AH49: Amplification | AI49: N | AJ49: N | AK49: N | AM49: N | AP49: =(100*(K49-K34))/AE49 | AQ49: =IF(AND(AP49>=80,AP49<=120),"PASS","FAIL")
